temp@ailp-ds:~/preritprograms/Allocator$ source venv/bin/activate
(venv) temp@ailp-ds:~/preritprograms/Allocator$ python main.py
Allocator is online.
Process Process-2:
Process Process-6:
Process Process-4:
Process Process-1:
Process Process-3:
Process Process-5:
Traceback (most recent call last):
  File "/home/temp/preritprograms/Allocator/venv/lib/python3.10/site-packages/urllib3/connectionpool.py", line 703, in urlopen
    httplib_response = self._make_request(
  File "/home/temp/preritprograms/Allocator/venv/lib/python3.10/site-packages/urllib3/connectionpool.py", line 449, in _make_request
    six.raise_from(e, None)
  File "<string>", line 3, in raise_from
  File "/home/temp/preritprograms/Allocator/venv/lib/python3.10/site-packages/urllib3/connectionpool.py", line 444, in _make_request
    httplib_response = conn.getresponse()
  File "/usr/lib/python3.10/http/client.py", line 1374, in getresponse
    response.begin()
  File "/usr/lib/python3.10/http/client.py", line 318, in begin
    version, status, reason = self._read_status()
  File "/usr/lib/python3.10/http/client.py", line 279, in _read_status
    line = str(self.fp.readline(_MAXLINE + 1), "iso-8859-1")
  File "/usr/lib/python3.10/socket.py", line 705, in readinto
    return self._sock.recv_into(b)
  File "/usr/lib/python3.10/ssl.py", line 1273, in recv_into
    return self.read(nbytes, buffer)
  File "/usr/lib/python3.10/ssl.py", line 1129, in read
    return self._sslobj.read(len, buffer)
ssl.SSLError: [SSL: WRONG_VERSION_NUMBER] wrong version number (_ssl.c:2548)

During handling of the above exception, another exception occurred:

Traceback (most recent call last):
  File "/home/temp/preritprograms/Allocator/venv/lib/python3.10/site-packages/requests/adapters.py", line 440, in send
Traceback (most recent call last):
    resp = conn.urlopen(
  File "/home/temp/preritprograms/Allocator/venv/lib/python3.10/site-packages/urllib3/connectionpool.py", line 703, in urlopen
    httplib_response = self._make_request(
  File "/home/temp/preritprograms/Allocator/venv/lib/python3.10/site-packages/urllib3/connectionpool.py", line 785, in urlopen
  File "/home/temp/preritprograms/Allocator/venv/lib/python3.10/site-packages/urllib3/connectionpool.py", line 449, in _make_request
    six.raise_from(e, None)
  File "<string>", line 3, in raise_from
  File "/home/temp/preritprograms/Allocator/venv/lib/python3.10/site-packages/urllib3/connectionpool.py", line 444, in _make_request
    httplib_response = conn.getresponse()
  File "/usr/lib/python3.10/http/client.py", line 1374, in getresponse
    response.begin()
  File "/usr/lib/python3.10/http/client.py", line 318, in begin
    version, status, reason = self._read_status()
  File "/usr/lib/python3.10/http/client.py", line 287, in _read_status
    raise RemoteDisconnected("Remote end closed connection without"
Traceback (most recent call last):
Traceback (most recent call last):
http.client.RemoteDisconnected: Remote end closed connection without response

During handling of the above exception, another exception occurred:

Traceback (most recent call last):
Traceback (most recent call last):
  File "/home/temp/preritprograms/Allocator/venv/lib/python3.10/site-packages/urllib3/connectionpool.py", line 703, in urlopen
    httplib_response = self._make_request(
    retries = retries.increment(
  File "/home/temp/preritprograms/Allocator/venv/lib/python3.10/site-packages/urllib3/connectionpool.py", line 703, in urlopen
    httplib_response = self._make_request(
  File "/home/temp/preritprograms/Allocator/venv/lib/python3.10/site-packages/urllib3/connectionpool.py", line 449, in _make_request
    six.raise_from(e, None)
  File "/home/temp/preritprograms/Allocator/venv/lib/python3.10/site-packages/urllib3/util/retry.py", line 592, in increment
  File "/home/temp/preritprograms/Allocator/venv/lib/python3.10/site-packages/requests/adapters.py", line 440, in send
    resp = conn.urlopen(
  File "/home/temp/preritprograms/Allocator/venv/lib/python3.10/site-packages/urllib3/connectionpool.py", line 449, in _make_request
    six.raise_from(e, None)
  File "/home/temp/preritprograms/Allocator/venv/lib/python3.10/site-packages/urllib3/connectionpool.py", line 785, in urlopen
    retries = retries.increment(
  File "<string>", line 3, in raise_from
  File "/home/temp/preritprograms/Allocator/venv/lib/python3.10/site-packages/urllib3/connectionpool.py", line 703, in urlopen
    httplib_response = self._make_request(
  File "<string>", line 3, in raise_from
  File "/home/temp/preritprograms/Allocator/venv/lib/python3.10/site-packages/urllib3/util/retry.py", line 550, in increment
    raise six.reraise(type(error), error, _stacktrace)
Traceback (most recent call last):
  File "/home/temp/preritprograms/Allocator/venv/lib/python3.10/site-packages/urllib3/connectionpool.py", line 444, in _make_request
    httplib_response = conn.getresponse()
Traceback (most recent call last):
  File "/home/temp/preritprograms/Allocator/venv/lib/python3.10/site-packages/urllib3/connectionpool.py", line 449, in _make_request
    six.raise_from(e, None)
  File "/home/temp/preritprograms/Allocator/venv/lib/python3.10/site-packages/urllib3/connectionpool.py", line 444, in _make_request
    httplib_response = conn.getresponse()
  File "/home/temp/preritprograms/Allocator/venv/lib/python3.10/site-packages/urllib3/packages/six.py", line 769, in reraise
    raise value.with_traceback(tb)
  File "/usr/lib/python3.10/http/client.py", line 1374, in getresponse
    response.begin()
  File "<string>", line 3, in raise_from
  File "/usr/lib/python3.10/http/client.py", line 1374, in getresponse
    response.begin()
  File "/home/temp/preritprograms/Allocator/venv/lib/python3.10/site-packages/urllib3/connectionpool.py", line 703, in urlopen
    httplib_response = self._make_request(
  File "/home/temp/preritprograms/Allocator/venv/lib/python3.10/site-packages/urllib3/connectionpool.py", line 703, in urlopen
    httplib_response = self._make_request(
  File "/usr/lib/python3.10/http/client.py", line 318, in begin
    version, status, reason = self._read_status()
  File "/home/temp/preritprograms/Allocator/venv/lib/python3.10/site-packages/urllib3/connectionpool.py", line 444, in _make_request
    httplib_response = conn.getresponse()
  File "/home/temp/preritprograms/Allocator/venv/lib/python3.10/site-packages/urllib3/connectionpool.py", line 703, in urlopen
    httplib_response = self._make_request(
  File "/usr/lib/python3.10/http/client.py", line 318, in begin
    version, status, reason = self._read_status()
  File "/home/temp/preritprograms/Allocator/venv/lib/python3.10/site-packages/urllib3/connectionpool.py", line 449, in _make_request
    six.raise_from(e, None)
  File "/home/temp/preritprograms/Allocator/venv/lib/python3.10/site-packages/urllib3/connectionpool.py", line 449, in _make_request
    six.raise_from(e, None)
  File "/usr/lib/python3.10/http/client.py", line 279, in _read_status
    line = str(self.fp.readline(_MAXLINE + 1), "iso-8859-1")
  File "/usr/lib/python3.10/http/client.py", line 1374, in getresponse
    response.begin()
  File "/home/temp/preritprograms/Allocator/venv/lib/python3.10/site-packages/urllib3/connectionpool.py", line 449, in _make_request
    six.raise_from(e, None)
  File "/usr/lib/python3.10/http/client.py", line 279, in _read_status
    line = str(self.fp.readline(_MAXLINE + 1), "iso-8859-1")
  File "<string>", line 3, in raise_from
    raise MaxRetryError(_pool, url, error or ResponseError(cause))
  File "<string>", line 3, in raise_from
  File "/usr/lib/python3.10/socket.py", line 705, in readinto
    return self._sock.recv_into(b)
  File "/usr/lib/python3.10/http/client.py", line 318, in begin
    version, status, reason = self._read_status()
  File "<string>", line 3, in raise_from
  File "/usr/lib/python3.10/socket.py", line 705, in readinto
    return self._sock.recv_into(b)
  File "/home/temp/preritprograms/Allocator/venv/lib/python3.10/site-packages/urllib3/connectionpool.py", line 444, in _make_request
    httplib_response = conn.getresponse()
  File "/usr/lib/python3.10/ssl.py", line 1273, in recv_into
    return self.read(nbytes, buffer)
  File "/usr/lib/python3.10/http/client.py", line 1374, in getresponse
    response.begin()
  File "/home/temp/preritprograms/Allocator/venv/lib/python3.10/site-packages/urllib3/connectionpool.py", line 444, in _make_request
    httplib_response = conn.getresponse()
  File "/usr/lib/python3.10/ssl.py", line 1273, in recv_into
    return self.read(nbytes, buffer)
  File "/usr/lib/python3.10/http/client.py", line 279, in _read_status
    line = str(self.fp.readline(_MAXLINE + 1), "iso-8859-1")
  File "/home/temp/preritprograms/Allocator/venv/lib/python3.10/site-packages/urllib3/connectionpool.py", line 444, in _make_request
    httplib_response = conn.getresponse()
urllib3.exceptions.MaxRetryError: HTTPSConnectionPool(host='api.alpaca.markets', port=443): Max retries exceeded with url: /v2/account (Caused by SSLError(SSLError(1, '[SSL: WRONG_VERSION_NUMBER] wrong version number (_ssl.c:2548)')))
  File "/usr/lib/python3.10/ssl.py", line 1129, in read
    return self._sslobj.read(len, buffer)
  File "/usr/lib/python3.10/http/client.py", line 318, in begin
    version, status, reason = self._read_status()
  File "/usr/lib/python3.10/http/client.py", line 1374, in getresponse
    response.begin()
  File "/usr/lib/python3.10/ssl.py", line 1129, in read
    return self._sslobj.read(len, buffer)
  File "/usr/lib/python3.10/socket.py", line 705, in readinto
    return self._sock.recv_into(b)
  File "/usr/lib/python3.10/http/client.py", line 1374, in getresponse
    response.begin()

During handling of the above exception, another exception occurred:

  File "/usr/lib/python3.10/http/client.py", line 287, in _read_status
    raise RemoteDisconnected("Remote end closed connection without"
  File "/usr/lib/python3.10/http/client.py", line 318, in begin
    version, status, reason = self._read_status()
  File "/usr/lib/python3.10/ssl.py", line 1273, in recv_into
    return self.read(nbytes, buffer)
  File "/usr/lib/python3.10/http/client.py", line 318, in begin
    version, status, reason = self._read_status()
ssl.SSLError: [SSL: WRONG_VERSION_NUMBER] wrong version number (_ssl.c:2548)
Traceback (most recent call last):
  File "/usr/lib/python3.10/http/client.py", line 279, in _read_status
    line = str(self.fp.readline(_MAXLINE + 1), "iso-8859-1")
  File "/usr/lib/python3.10/ssl.py", line 1129, in read
    return self._sslobj.read(len, buffer)
urllib3.exceptions.ProtocolError: ('Connection aborted.', RemoteDisconnected('Remote end closed connection without response'))
ssl.SSLError: [SSL: WRONG_VERSION_NUMBER] wrong version number (_ssl.c:2548)
  File "/usr/lib/python3.10/http/client.py", line 279, in _read_status
    line = str(self.fp.readline(_MAXLINE + 1), "iso-8859-1")

During handling of the above exception, another exception occurred:

  File "/home/temp/preritprograms/Allocator/main.py", line 252, in <module>
  File "/usr/lib/python3.10/socket.py", line 705, in readinto
    return self._sock.recv_into(b)

During handling of the above exception, another exception occurred:


During handling of the above exception, another exception occurred:

Traceback (most recent call last):
Traceback (most recent call last):
  File "/usr/lib/python3.10/socket.py", line 705, in readinto
    return self._sock.recv_into(b)
Traceback (most recent call last):
ssl.SSLError: [SSL: WRONG_VERSION_NUMBER] wrong version number (_ssl.c:2548)
  File "/usr/lib/python3.10/ssl.py", line 1273, in recv_into
    return self.read(nbytes, buffer)
  File "/usr/lib/python3.10/ssl.py", line 1273, in recv_into
    return self.read(nbytes, buffer)
  File "/home/temp/preritprograms/Allocator/venv/lib/python3.10/site-packages/requests/adapters.py", line 440, in send
    resp = conn.urlopen(

During handling of the above exception, another exception occurred:

  File "/usr/lib/python3.10/ssl.py", line 1129, in read
    return self._sslobj.read(len, buffer)
  File "/usr/lib/python3.10/ssl.py", line 1129, in read
    return self._sslobj.read(len, buffer)
  File "/home/temp/preritprograms/Allocator/venv/lib/python3.10/site-packages/requests/adapters.py", line 440, in send
    resp = conn.urlopen(
  File "/home/temp/preritprograms/Allocator/venv/lib/python3.10/site-packages/urllib3/connectionpool.py", line 785, in urlopen
    retries = retries.increment(
  File "/home/temp/preritprograms/Allocator/venv/lib/python3.10/site-packages/urllib3/connectionpool.py", line 785, in urlopen
    retries = retries.increment(
  File "/usr/lib/python3.10/multiprocessing/process.py", line 315, in _bootstrap
    self.run()
Traceback (most recent call last):
  File "/home/temp/preritprograms/Allocator/venv/lib/python3.10/site-packages/urllib3/util/retry.py", line 592, in increment
    raise MaxRetryError(_pool, url, error or ResponseError(cause))
  File "/home/temp/preritprograms/Allocator/venv/lib/python3.10/site-packages/urllib3/util/retry.py", line 592, in increment
    raise MaxRetryError(_pool, url, error or ResponseError(cause))
    main()
  File "/usr/lib/python3.10/multiprocessing/process.py", line 108, in run
    self._target(*self._args, **self._kwargs)
ssl.SSLError: [SSL: WRONG_VERSION_NUMBER] wrong version number (_ssl.c:2548)
ssl.SSLError: [SSL: WRONG_VERSION_NUMBER] wrong version number (_ssl.c:2548)
  File "/home/temp/preritprograms/Allocator/main.py", line 237, in main
  File "/home/temp/preritprograms/Allocator/venv/lib/python3.10/site-packages/requests/adapters.py", line 440, in send
    resp = conn.urlopen(
  File "/home/temp/preritprograms/Allocator/main.py", line 94, in fractional_order
    alpaca.submit_order(
urllib3.exceptions.MaxRetryError: HTTPSConnectionPool(host='api.alpaca.markets', port=443): Max retries exceeded with url: /v2/orders (Caused by SSLError(SSLError(1, '[SSL: WRONG_VERSION_NUMBER] wrong version number (_ssl.c:2548)')))

During handling of the above exception, another exception occurred:

urllib3.exceptions.MaxRetryError: HTTPSConnectionPool(host='api.alpaca.markets', port=443): Max retries exceeded with url: /v2/orders (Caused by SSLError(SSLError(1, '[SSL: WRONG_VERSION_NUMBER] wrong version number (_ssl.c:2548)')))

During handling of the above exception, another exception occurred:


During handling of the above exception, another exception occurred:

  File "/home/temp/preritprograms/Allocator/venv/lib/python3.10/site-packages/urllib3/connectionpool.py", line 785, in urlopen
    retries = retries.increment(
  File "/home/temp/preritprograms/Allocator/venv/lib/python3.10/site-packages/alpaca_trade_api/rest.py", line 421, in submit_order
    resp = self.post('/orders', params)

During handling of the above exception, another exception occurred:

  File "/home/temp/preritprograms/Allocator/venv/lib/python3.10/site-packages/alpaca_trade_api/rest.py", line 253, in post
    return self._request('POST', path, data)
Traceback (most recent call last):
Traceback (most recent call last):
Traceback (most recent call last):
  File "/home/temp/preritprograms/Allocator/venv/lib/python3.10/site-packages/urllib3/util/retry.py", line 592, in increment
    raise MaxRetryError(_pool, url, error or ResponseError(cause))
Traceback (most recent call last):
  File "/home/temp/preritprograms/Allocator/venv/lib/python3.10/site-packages/alpaca_trade_api/rest.py", line 213, in _request
    return self._one_request(method, url, opts, retry)
  File "/home/temp/preritprograms/Allocator/venv/lib/python3.10/site-packages/requests/adapters.py", line 440, in send
    resp = conn.urlopen(
  File "/home/temp/preritprograms/Allocator/venv/lib/python3.10/site-packages/alpaca_trade_api/rest.py", line 232, in _one_request
    resp = self._session.request(method, url, **opts)
    print(compile_message())
  File "/home/temp/preritprograms/Allocator/venv/lib/python3.10/site-packages/requests/adapters.py", line 440, in send
    resp = conn.urlopen(
  File "/home/temp/preritprograms/Allocator/venv/lib/python3.10/site-packages/urllib3/connectionpool.py", line 785, in urlopen
    retries = retries.increment(
  File "/home/temp/preritprograms/Allocator/venv/lib/python3.10/site-packages/requests/sessions.py", line 529, in request
    resp = self.send(prep, **send_kwargs)
urllib3.exceptions.MaxRetryError: HTTPSConnectionPool(host='api.alpaca.markets', port=443): Max retries exceeded with url: /v2/orders (Caused by SSLError(SSLError(1, '[SSL: WRONG_VERSION_NUMBER] wrong version number (_ssl.c:2548)')))
  File "/usr/lib/python3.10/multiprocessing/process.py", line 315, in _bootstrap
    self.run()
  File "/home/temp/preritprograms/Allocator/main.py", line 136, in compile_message
  File "/home/temp/preritprograms/Allocator/venv/lib/python3.10/site-packages/urllib3/connectionpool.py", line 785, in urlopen
    retries = retries.increment(
  File "/home/temp/preritprograms/Allocator/venv/lib/python3.10/site-packages/urllib3/util/retry.py", line 592, in increment
    raise MaxRetryError(_pool, url, error or ResponseError(cause))
  File "/home/temp/preritprograms/Allocator/venv/lib/python3.10/site-packages/requests/sessions.py", line 645, in send
    r = adapter.send(request, **kwargs)
  File "/usr/lib/python3.10/multiprocessing/process.py", line 315, in _bootstrap
    self.run()

During handling of the above exception, another exception occurred:

  File "/usr/lib/python3.10/multiprocessing/process.py", line 108, in run
    self._target(*self._args, **self._kwargs)
  File "/home/temp/preritprograms/Allocator/venv/lib/python3.10/site-packages/urllib3/util/retry.py", line 592, in increment
    raise MaxRetryError(_pool, url, error or ResponseError(cause))
  File "/home/temp/preritprograms/Allocator/venv/lib/python3.10/site-packages/requests/adapters.py", line 501, in send
    raise ConnectionError(err, request=request)
  File "/usr/lib/python3.10/multiprocessing/process.py", line 108, in run
    self._target(*self._args, **self._kwargs)
Traceback (most recent call last):
  File "/home/temp/preritprograms/Allocator/main.py", line 94, in fractional_order
    alpaca.submit_order(
urllib3.exceptions.MaxRetryError: HTTPSConnectionPool(host='api.alpaca.markets', port=443): Max retries exceeded with url: /v2/orders (Caused by SSLError(SSLError(1, '[SSL: WRONG_VERSION_NUMBER] wrong version number (_ssl.c:2548)')))
  File "/home/temp/preritprograms/Allocator/main.py", line 94, in fractional_order
    alpaca.submit_order(
requests.exceptions.ConnectionError: ('Connection aborted.', RemoteDisconnected('Remote end closed connection without response'))
urllib3.exceptions.MaxRetryError: HTTPSConnectionPool(host='api.alpaca.markets', port=443): Max retries exceeded with url: /v2/orders (Caused by SSLError(SSLError(1, '[SSL: WRONG_VERSION_NUMBER] wrong version number (_ssl.c:2548)')))
  File "/home/temp/preritprograms/Allocator/venv/lib/python3.10/site-packages/alpaca_trade_api/rest.py", line 421, in submit_order
    resp = self.post('/orders', params)
    quantities = calculate_quantities()

During handling of the above exception, another exception occurred:

  File "/home/temp/preritprograms/Allocator/venv/lib/python3.10/site-packages/alpaca_trade_api/rest.py", line 421, in submit_order
    resp = self.post('/orders', params)

During handling of the above exception, another exception occurred:

  File "/home/temp/preritprograms/Allocator/venv/lib/python3.10/site-packages/alpaca_trade_api/rest.py", line 253, in post
    return self._request('POST', path, data)
  File "/usr/lib/python3.10/multiprocessing/process.py", line 315, in _bootstrap
    self.run()
  File "/home/temp/preritprograms/Allocator/main.py", line 67, in calculate_quantities
  File "/usr/lib/python3.10/multiprocessing/process.py", line 108, in run
    self._target(*self._args, **self._kwargs)
Traceback (most recent call last):
  File "/home/temp/preritprograms/Allocator/venv/lib/python3.10/site-packages/alpaca_trade_api/rest.py", line 253, in post
    return self._request('POST', path, data)
Traceback (most recent call last):
  File "/home/temp/preritprograms/Allocator/venv/lib/python3.10/site-packages/alpaca_trade_api/rest.py", line 213, in _request
    return self._one_request(method, url, opts, retry)
  File "/home/temp/preritprograms/Allocator/main.py", line 94, in fractional_order
    alpaca.submit_order(
  File "/home/temp/preritprograms/Allocator/venv/lib/python3.10/site-packages/alpaca_trade_api/rest.py", line 213, in _request
    return self._one_request(method, url, opts, retry)
  File "/home/temp/preritprograms/Allocator/venv/lib/python3.10/site-packages/alpaca_trade_api/rest.py", line 232, in _one_request
    resp = self._session.request(method, url, **opts)
  File "/usr/lib/python3.10/multiprocessing/process.py", line 315, in _bootstrap
    self.run()
    cash = cash_balance()
  File "/home/temp/preritprograms/Allocator/venv/lib/python3.10/site-packages/alpaca_trade_api/rest.py", line 421, in submit_order
    resp = self.post('/orders', params)
  File "/home/temp/preritprograms/Allocator/venv/lib/python3.10/site-packages/alpaca_trade_api/rest.py", line 232, in _one_request
    resp = self._session.request(method, url, **opts)
  File "/home/temp/preritprograms/Allocator/venv/lib/python3.10/site-packages/requests/sessions.py", line 529, in request
    resp = self.send(prep, **send_kwargs)
  File "/home/temp/preritprograms/Allocator/venv/lib/python3.10/site-packages/requests/sessions.py", line 529, in request
    resp = self.send(prep, **send_kwargs)
  File "/usr/lib/python3.10/multiprocessing/process.py", line 315, in _bootstrap
    self.run()
  File "/usr/lib/python3.10/multiprocessing/process.py", line 108, in run
    self._target(*self._args, **self._kwargs)
  File "/home/temp/preritprograms/Allocator/main.py", line 58, in cash_balance
  File "/home/temp/preritprograms/Allocator/venv/lib/python3.10/site-packages/alpaca_trade_api/rest.py", line 253, in post
    return self._request('POST', path, data)
  File "/home/temp/preritprograms/Allocator/venv/lib/python3.10/site-packages/requests/sessions.py", line 645, in send
    r = adapter.send(request, **kwargs)
  File "/home/temp/preritprograms/Allocator/venv/lib/python3.10/site-packages/requests/sessions.py", line 645, in send
    r = adapter.send(request, **kwargs)
  File "/home/temp/preritprograms/Allocator/venv/lib/python3.10/site-packages/requests/adapters.py", line 517, in send
    raise SSLError(e, request=request)
  File "/usr/lib/python3.10/multiprocessing/process.py", line 108, in run
    self._target(*self._args, **self._kwargs)
  File "/home/temp/preritprograms/Allocator/main.py", line 94, in fractional_order
    alpaca.submit_order(
  File "/home/temp/preritprograms/Allocator/venv/lib/python3.10/site-packages/alpaca_trade_api/rest.py", line 213, in _request
    return self._one_request(method, url, opts, retry)
  File "/home/temp/preritprograms/Allocator/venv/lib/python3.10/site-packages/requests/adapters.py", line 517, in send
    raise SSLError(e, request=request)
  File "/home/temp/preritprograms/Allocator/main.py", line 94, in fractional_order
    alpaca.submit_order(
requests.exceptions.SSLError: HTTPSConnectionPool(host='api.alpaca.markets', port=443): Max retries exceeded with url: /v2/orders (Caused by SSLError(SSLError(1, '[SSL: WRONG_VERSION_NUMBER] wrong version number (_ssl.c:2548)')))
  File "/home/temp/preritprograms/Allocator/venv/lib/python3.10/site-packages/alpaca_trade_api/rest.py", line 421, in submit_order
    resp = self.post('/orders', params)
  File "/home/temp/preritprograms/Allocator/venv/lib/python3.10/site-packages/alpaca_trade_api/rest.py", line 232, in _one_request
    resp = self._session.request(method, url, **opts)
  File "/home/temp/preritprograms/Allocator/venv/lib/python3.10/site-packages/alpaca_trade_api/rest.py", line 421, in submit_order
    resp = self.post('/orders', params)
  File "/home/temp/preritprograms/Allocator/venv/lib/python3.10/site-packages/requests/sessions.py", line 529, in request
    resp = self.send(prep, **send_kwargs)
requests.exceptions.SSLError: HTTPSConnectionPool(host='api.alpaca.markets', port=443): Max retries exceeded with url: /v2/orders (Caused by SSLError(SSLError(1, '[SSL: WRONG_VERSION_NUMBER] wrong version number (_ssl.c:2548)')))
    account = alpaca.get_account()
  File "/home/temp/preritprograms/Allocator/venv/lib/python3.10/site-packages/alpaca_trade_api/rest.py", line 253, in post
    return self._request('POST', path, data)
  File "/home/temp/preritprograms/Allocator/venv/lib/python3.10/site-packages/alpaca_trade_api/rest.py", line 253, in post
    return self._request('POST', path, data)
  File "/home/temp/preritprograms/Allocator/venv/lib/python3.10/site-packages/requests/sessions.py", line 645, in send
    r = adapter.send(request, **kwargs)
  File "/home/temp/preritprograms/Allocator/venv/lib/python3.10/site-packages/alpaca_trade_api/rest.py", line 272, in get_account
  File "/home/temp/preritprograms/Allocator/venv/lib/python3.10/site-packages/alpaca_trade_api/rest.py", line 213, in _request
    return self._one_request(method, url, opts, retry)
  File "/home/temp/preritprograms/Allocator/venv/lib/python3.10/site-packages/alpaca_trade_api/rest.py", line 213, in _request
    return self._one_request(method, url, opts, retry)
  File "/home/temp/preritprograms/Allocator/venv/lib/python3.10/site-packages/requests/adapters.py", line 517, in send
    raise SSLError(e, request=request)
  File "/home/temp/preritprograms/Allocator/venv/lib/python3.10/site-packages/alpaca_trade_api/rest.py", line 232, in _one_request
    resp = self._session.request(method, url, **opts)
  File "/home/temp/preritprograms/Allocator/venv/lib/python3.10/site-packages/alpaca_trade_api/rest.py", line 232, in _one_request
    resp = self._session.request(method, url, **opts)
  File "/home/temp/preritprograms/Allocator/venv/lib/python3.10/site-packages/requests/sessions.py", line 529, in request
    resp = self.send(prep, **send_kwargs)
  File "/home/temp/preritprograms/Allocator/venv/lib/python3.10/site-packages/requests/sessions.py", line 529, in request
    resp = self.send(prep, **send_kwargs)
requests.exceptions.SSLError: HTTPSConnectionPool(host='api.alpaca.markets', port=443): Max retries exceeded with url: /v2/orders (Caused by SSLError(SSLError(1, '[SSL: WRONG_VERSION_NUMBER] wrong version number (_ssl.c:2548)')))
  File "/home/temp/preritprograms/Allocator/venv/lib/python3.10/site-packages/requests/sessions.py", line 645, in send
    r = adapter.send(request, **kwargs)
  File "/home/temp/preritprograms/Allocator/venv/lib/python3.10/site-packages/requests/sessions.py", line 645, in send
    r = adapter.send(request, **kwargs)
  File "/home/temp/preritprograms/Allocator/venv/lib/python3.10/site-packages/requests/adapters.py", line 517, in send
    raise SSLError(e, request=request)
  File "/home/temp/preritprograms/Allocator/venv/lib/python3.10/site-packages/requests/adapters.py", line 517, in send
    raise SSLError(e, request=request)
requests.exceptions.SSLError: HTTPSConnectionPool(host='api.alpaca.markets', port=443): Max retries exceeded with url: /v2/orders (Caused by SSLError(SSLError(1, '[SSL: WRONG_VERSION_NUMBER] wrong version number (_ssl.c:2548)')))
requests.exceptions.SSLError: HTTPSConnectionPool(host='api.alpaca.markets', port=443): Max retries exceeded with url: /v2/orders (Caused by SSLError(SSLError(1, '[SSL: WRONG_VERSION_NUMBER] wrong version number (_ssl.c:2548)')))
    resp = self.get('/account')
  File "/home/temp/preritprograms/Allocator/venv/lib/python3.10/site-packages/alpaca_trade_api/rest.py", line 250, in get
    return self._request('GET', path, data)
  File "/home/temp/preritprograms/Allocator/venv/lib/python3.10/site-packages/alpaca_trade_api/rest.py", line 213, in _request
    return self._one_request(method, url, opts, retry)
  File "/home/temp/preritprograms/Allocator/venv/lib/python3.10/site-packages/alpaca_trade_api/rest.py", line 232, in _one_request
    resp = self._session.request(method, url, **opts)
  File "/home/temp/preritprograms/Allocator/venv/lib/python3.10/site-packages/requests/sessions.py", line 529, in request
    resp = self.send(prep, **send_kwargs)
  File "/home/temp/preritprograms/Allocator/venv/lib/python3.10/site-packages/requests/sessions.py", line 645, in send
    r = adapter.send(request, **kwargs)
  File "/home/temp/preritprograms/Allocator/venv/lib/python3.10/site-packages/requests/adapters.py", line 517, in send
    raise SSLError(e, request=request)
requests.exceptions.SSLError: HTTPSConnectionPool(host='api.alpaca.markets', port=443): Max retries exceeded with url: /v2/account (Caused by SSLError(SSLError(1, '[SSL: WRONG_VERSION_NUMBER] wrong version number (_ssl.c:2548)')))
(venv) temp@ailp-ds:~/preritprograms/Allocator$ exit
